INFO     common.recordlog:assertion.py:46 error_code包含断言成功