INFO     common.recordlog:assertion.py:46 message包含断言成功